#VRML_SIM R2023b utf8

EXTERNPROTO "https://raw.githubusercontent.com/cyberbotics/webots/R2023b/projects/objects/backgrounds/protos/TexturedBackground.proto"
EXTERNPROTO "https://raw.githubusercontent.com/cyberbotics/webots/R2023b/projects/objects/backgrounds/protos/TexturedBackgroundLight.proto"
EXTERNPROTO "https://raw.githubusercontent.com/cyberbotics/webots/R2023b/projects/objects/floors/protos/RectangleArena.proto"

WorldInfo {
}
Viewpoint {
  orientation -0.3863750653396369 -0.25987642437124564 0.8849737583340015 4.215416254778619
  position 0.242113857239544 0.7520241743744681 0.7729550103152104
}
TexturedBackground {
}
TexturedBackgroundLight {
}
RectangleArena {
}
Robot {
  translation -7.566432864398681e-17 1.0842333420580505e-17 -0.010246514180557206
  rotation -0.2819843060599629 -0.3873964784900575 -0.8777293544079426 1.8140220677757373e-16
  children [
    DEF Body Pose {
      translation 0 0 0.05
      children [
        Shape {
          appearance PBRAppearance {
            baseColor 0 0 1
            roughness 1
            metalness 0
          }
          geometry Cylinder {
            height 0.08
            radius 0.05
          }
        }
      ]
    }
    HingeJoint {
      jointParameters HingeJointParameters {
        anchor 0.055 0 0.035
      }
      device [
        RotationalMotor {
          name "motor_1"
        }
      ]
      endPoint Solid {
        rotation 1 0 0 0
        children [
          Shape {
            geometry Cylinder {
              height 0.01
              radius 0.025
            }
          }
        ]
      }
    }
  ]
  boundingObject USE Body
  physics Physics {
  }
}
